/home/deni/Programming/Python/telegram-bot/venv/lib/python3.11/site-packages/telegram/ext/_application.py:727: RuntimeWarning: coroutine 'Updater.start_polling' was never awaited
  return self.__run(
RuntimeWarning: Enable tracemalloc to get the object allocation traceback
2023-07-05 22:37:52,610 - httpx - INFO - HTTP Request: POST https://api.telegram.org/bot5658001862:AAGe0eClJ5KlTQR0m35X7tPOa5Tsbu5oJH4/getMe "HTTP/1.1 200 OK"
2023-07-05 22:37:53,011 - httpx - INFO - HTTP Request: POST https://api.telegram.org/bot5658001862:AAGe0eClJ5KlTQR0m35X7tPOa5Tsbu5oJH4/deleteWebhook "HTTP/1.1 200 OK"
2023-07-05 22:37:53,014 - telegram.ext.Application - INFO - Application started
2023-07-05 22:37:58,720 - httpx - INFO - HTTP Request: POST https://api.telegram.org/bot5658001862:AAGe0eClJ5KlTQR0m35X7tPOa5Tsbu5oJH4/getUpdates "HTTP/1.1 409 Conflict"
2023-07-05 22:37:58,722 - telegram.ext.Updater - ERROR - Error while getting Updates: Conflict: terminated by other getUpdates request; make sure that only one bot instance is running
2023-07-05 22:37:58,723 - telegram.ext.Application - ERROR - No error handlers are registered, logging exception.
Traceback (most recent call last):
  File "/home/deni/Programming/Python/telegram-bot/venv/lib/python3.11/site-packages/telegram/ext/_updater.py", line 607, in _network_loop_retry
    if not await action_cb():
           ^^^^^^^^^^^^^^^^^
  File "/home/deni/Programming/Python/telegram-bot/venv/lib/python3.11/site-packages/telegram/ext/_updater.py", line 335, in polling_action_cb
    raise exc
  File "/home/deni/Programming/Python/telegram-bot/venv/lib/python3.11/site-packages/telegram/ext/_updater.py", line 320, in polling_action_cb
    updates = await self.bot.get_updates(
              ^^^^^^^^^^^^^^^^^^^^^^^^^^^
  File "/home/deni/Programming/Python/telegram-bot/venv/lib/python3.11/site-packages/telegram/ext/_extbot.py", line 543, in get_updates
    updates = await super().get_updates(
              ^^^^^^^^^^^^^^^^^^^^^^^^^^
  File "/home/deni/Programming/Python/telegram-bot/venv/lib/python3.11/site-packages/telegram/_bot.py", line 381, in decorator
    result = await func(self, *args, **kwargs)  # skipcq: PYL-E1102
             ^^^^^^^^^^^^^^^^^^^^^^^^^^^^^^^^^
  File "/home/deni/Programming/Python/telegram-bot/venv/lib/python3.11/site-packages/telegram/_bot.py", line 3661, in get_updates
    await self._post(
  File "/home/deni/Programming/Python/telegram-bot/venv/lib/python3.11/site-packages/telegram/_bot.py", line 469, in _post
    return await self._do_post(
           ^^^^^^^^^^^^^^^^^^^^
  File "/home/deni/Programming/Python/telegram-bot/venv/lib/python3.11/site-packages/telegram/ext/_extbot.py", line 325, in _do_post
    return await super()._do_post(
           ^^^^^^^^^^^^^^^^^^^^^^^
  File "/home/deni/Programming/Python/telegram-bot/venv/lib/python3.11/site-packages/telegram/_bot.py", line 497, in _do_post
    return await request.post(
           ^^^^^^^^^^^^^^^^^^^
  File "/home/deni/Programming/Python/telegram-bot/venv/lib/python3.11/site-packages/telegram/request/_baserequest.py", line 168, in post
    result = await self._request_wrapper(
             ^^^^^^^^^^^^^^^^^^^^^^^^^^^^
  File "/home/deni/Programming/Python/telegram-bot/venv/lib/python3.11/site-packages/telegram/request/_baserequest.py", line 330, in _request_wrapper
    raise Conflict(message)
telegram.error.Conflict: Conflict: terminated by other getUpdates request; make sure that only one bot instance is running
2023-07-05 22:38:04,494 - httpx - INFO - HTTP Request: POST https://api.telegram.org/bot5658001862:AAGe0eClJ5KlTQR0m35X7tPOa5Tsbu5oJH4/getUpdates "HTTP/1.1 409 Conflict"
2023-07-05 22:38:04,495 - telegram.ext.Updater - ERROR - Error while getting Updates: Conflict: terminated by other getUpdates request; make sure that only one bot instance is running
2023-07-05 22:38:04,495 - telegram.ext.Application - ERROR - No error handlers are registered, logging exception.
Traceback (most recent call last):
  File "/home/deni/Programming/Python/telegram-bot/venv/lib/python3.11/site-packages/telegram/ext/_updater.py", line 607, in _network_loop_retry
    if not await action_cb():
           ^^^^^^^^^^^^^^^^^
  File "/home/deni/Programming/Python/telegram-bot/venv/lib/python3.11/site-packages/telegram/ext/_updater.py", line 335, in polling_action_cb
    raise exc
  File "/home/deni/Programming/Python/telegram-bot/venv/lib/python3.11/site-packages/telegram/ext/_updater.py", line 320, in polling_action_cb
    updates = await self.bot.get_updates(
              ^^^^^^^^^^^^^^^^^^^^^^^^^^^
  File "/home/deni/Programming/Python/telegram-bot/venv/lib/python3.11/site-packages/telegram/ext/_extbot.py", line 543, in get_updates
    updates = await super().get_updates(
              ^^^^^^^^^^^^^^^^^^^^^^^^^^
  File "/home/deni/Programming/Python/telegram-bot/venv/lib/python3.11/site-packages/telegram/_bot.py", line 381, in decorator
    result = await func(self, *args, **kwargs)  # skipcq: PYL-E1102
             ^^^^^^^^^^^^^^^^^^^^^^^^^^^^^^^^^
  File "/home/deni/Programming/Python/telegram-bot/venv/lib/python3.11/site-packages/telegram/_bot.py", line 3661, in get_updates
    await self._post(
  File "/home/deni/Programming/Python/telegram-bot/venv/lib/python3.11/site-packages/telegram/_bot.py", line 469, in _post
    return await self._do_post(
           ^^^^^^^^^^^^^^^^^^^^
  File "/home/deni/Programming/Python/telegram-bot/venv/lib/python3.11/site-packages/telegram/ext/_extbot.py", line 325, in _do_post
    return await super()._do_post(
           ^^^^^^^^^^^^^^^^^^^^^^^
  File "/home/deni/Programming/Python/telegram-bot/venv/lib/python3.11/site-packages/telegram/_bot.py", line 497, in _do_post
    return await request.post(
           ^^^^^^^^^^^^^^^^^^^
  File "/home/deni/Programming/Python/telegram-bot/venv/lib/python3.11/site-packages/telegram/request/_baserequest.py", line 168, in post
    result = await self._request_wrapper(
             ^^^^^^^^^^^^^^^^^^^^^^^^^^^^
  File "/home/deni/Programming/Python/telegram-bot/venv/lib/python3.11/site-packages/telegram/request/_baserequest.py", line 330, in _request_wrapper
    raise Conflict(message)
telegram.error.Conflict: Conflict: terminated by other getUpdates request; make sure that only one bot instance is running
2023-07-05 22:38:11,521 - httpx - INFO - HTTP Request: POST https://api.telegram.org/bot5658001862:AAGe0eClJ5KlTQR0m35X7tPOa5Tsbu5oJH4/getUpdates "HTTP/1.1 409 Conflict"
2023-07-05 22:38:11,523 - telegram.ext.Updater - ERROR - Error while getting Updates: Conflict: terminated by other getUpdates request; make sure that only one bot instance is running
2023-07-05 22:38:11,523 - telegram.ext.Application - ERROR - No error handlers are registered, logging exception.
Traceback (most recent call last):
  File "/home/deni/Programming/Python/telegram-bot/venv/lib/python3.11/site-packages/telegram/ext/_updater.py", line 607, in _network_loop_retry
    if not await action_cb():
           ^^^^^^^^^^^^^^^^^
  File "/home/deni/Programming/Python/telegram-bot/venv/lib/python3.11/site-packages/telegram/ext/_updater.py", line 335, in polling_action_cb
    raise exc
  File "/home/deni/Programming/Python/telegram-bot/venv/lib/python3.11/site-packages/telegram/ext/_updater.py", line 320, in polling_action_cb
    updates = await self.bot.get_updates(
              ^^^^^^^^^^^^^^^^^^^^^^^^^^^
  File "/home/deni/Programming/Python/telegram-bot/venv/lib/python3.11/site-packages/telegram/ext/_extbot.py", line 543, in get_updates
    updates = await super().get_updates(
              ^^^^^^^^^^^^^^^^^^^^^^^^^^
  File "/home/deni/Programming/Python/telegram-bot/venv/lib/python3.11/site-packages/telegram/_bot.py", line 381, in decorator
    result = await func(self, *args, **kwargs)  # skipcq: PYL-E1102
             ^^^^^^^^^^^^^^^^^^^^^^^^^^^^^^^^^
  File "/home/deni/Programming/Python/telegram-bot/venv/lib/python3.11/site-packages/telegram/_bot.py", line 3661, in get_updates
    await self._post(
  File "/home/deni/Programming/Python/telegram-bot/venv/lib/python3.11/site-packages/telegram/_bot.py", line 469, in _post
    return await self._do_post(
           ^^^^^^^^^^^^^^^^^^^^
  File "/home/deni/Programming/Python/telegram-bot/venv/lib/python3.11/site-packages/telegram/ext/_extbot.py", line 325, in _do_post
    return await super()._do_post(
           ^^^^^^^^^^^^^^^^^^^^^^^
  File "/home/deni/Programming/Python/telegram-bot/venv/lib/python3.11/site-packages/telegram/_bot.py", line 497, in _do_post
    return await request.post(
           ^^^^^^^^^^^^^^^^^^^
  File "/home/deni/Programming/Python/telegram-bot/venv/lib/python3.11/site-packages/telegram/request/_baserequest.py", line 168, in post
    result = await self._request_wrapper(
             ^^^^^^^^^^^^^^^^^^^^^^^^^^^^
  File "/home/deni/Programming/Python/telegram-bot/venv/lib/python3.11/site-packages/telegram/request/_baserequest.py", line 330, in _request_wrapper
    raise Conflict(message)
telegram.error.Conflict: Conflict: terminated by other getUpdates request; make sure that only one bot instance is running
2023-07-05 22:38:18,045 - httpx - INFO - HTTP Request: POST https://api.telegram.org/bot5658001862:AAGe0eClJ5KlTQR0m35X7tPOa5Tsbu5oJH4/getUpdates "HTTP/1.1 409 Conflict"
2023-07-05 22:38:18,047 - telegram.ext.Updater - ERROR - Error while getting Updates: Conflict: terminated by other getUpdates request; make sure that only one bot instance is running
2023-07-05 22:38:18,047 - telegram.ext.Application - ERROR - No error handlers are registered, logging exception.
Traceback (most recent call last):
  File "/home/deni/Programming/Python/telegram-bot/venv/lib/python3.11/site-packages/telegram/ext/_updater.py", line 607, in _network_loop_retry
    if not await action_cb():
           ^^^^^^^^^^^^^^^^^
  File "/home/deni/Programming/Python/telegram-bot/venv/lib/python3.11/site-packages/telegram/ext/_updater.py", line 335, in polling_action_cb
    raise exc
  File "/home/deni/Programming/Python/telegram-bot/venv/lib/python3.11/site-packages/telegram/ext/_updater.py", line 320, in polling_action_cb
    updates = await self.bot.get_updates(
              ^^^^^^^^^^^^^^^^^^^^^^^^^^^
  File "/home/deni/Programming/Python/telegram-bot/venv/lib/python3.11/site-packages/telegram/ext/_extbot.py", line 543, in get_updates
    updates = await super().get_updates(
              ^^^^^^^^^^^^^^^^^^^^^^^^^^
  File "/home/deni/Programming/Python/telegram-bot/venv/lib/python3.11/site-packages/telegram/_bot.py", line 381, in decorator
    result = await func(self, *args, **kwargs)  # skipcq: PYL-E1102
             ^^^^^^^^^^^^^^^^^^^^^^^^^^^^^^^^^
  File "/home/deni/Programming/Python/telegram-bot/venv/lib/python3.11/site-packages/telegram/_bot.py", line 3661, in get_updates
    await self._post(
  File "/home/deni/Programming/Python/telegram-bot/venv/lib/python3.11/site-packages/telegram/_bot.py", line 469, in _post
    return await self._do_post(
           ^^^^^^^^^^^^^^^^^^^^
  File "/home/deni/Programming/Python/telegram-bot/venv/lib/python3.11/site-packages/telegram/ext/_extbot.py", line 325, in _do_post
    return await super()._do_post(
           ^^^^^^^^^^^^^^^^^^^^^^^
  File "/home/deni/Programming/Python/telegram-bot/venv/lib/python3.11/site-packages/telegram/_bot.py", line 497, in _do_post
    return await request.post(
           ^^^^^^^^^^^^^^^^^^^
  File "/home/deni/Programming/Python/telegram-bot/venv/lib/python3.11/site-packages/telegram/request/_baserequest.py", line 168, in post
    result = await self._request_wrapper(
             ^^^^^^^^^^^^^^^^^^^^^^^^^^^^
  File "/home/deni/Programming/Python/telegram-bot/venv/lib/python3.11/site-packages/telegram/request/_baserequest.py", line 330, in _request_wrapper
    raise Conflict(message)
telegram.error.Conflict: Conflict: terminated by other getUpdates request; make sure that only one bot instance is running
2023-07-05 22:38:26,545 - httpx - INFO - HTTP Request: POST https://api.telegram.org/bot5658001862:AAGe0eClJ5KlTQR0m35X7tPOa5Tsbu5oJH4/getUpdates "HTTP/1.1 409 Conflict"
2023-07-05 22:38:26,546 - telegram.ext.Updater - ERROR - Error while getting Updates: Conflict: terminated by other getUpdates request; make sure that only one bot instance is running
2023-07-05 22:38:26,547 - telegram.ext.Application - ERROR - No error handlers are registered, logging exception.
Traceback (most recent call last):
  File "/home/deni/Programming/Python/telegram-bot/venv/lib/python3.11/site-packages/telegram/ext/_updater.py", line 607, in _network_loop_retry
    if not await action_cb():
           ^^^^^^^^^^^^^^^^^
  File "/home/deni/Programming/Python/telegram-bot/venv/lib/python3.11/site-packages/telegram/ext/_updater.py", line 335, in polling_action_cb
    raise exc
  File "/home/deni/Programming/Python/telegram-bot/venv/lib/python3.11/site-packages/telegram/ext/_updater.py", line 320, in polling_action_cb
    updates = await self.bot.get_updates(
              ^^^^^^^^^^^^^^^^^^^^^^^^^^^
  File "/home/deni/Programming/Python/telegram-bot/venv/lib/python3.11/site-packages/telegram/ext/_extbot.py", line 543, in get_updates
    updates = await super().get_updates(
              ^^^^^^^^^^^^^^^^^^^^^^^^^^
  File "/home/deni/Programming/Python/telegram-bot/venv/lib/python3.11/site-packages/telegram/_bot.py", line 381, in decorator
    result = await func(self, *args, **kwargs)  # skipcq: PYL-E1102
             ^^^^^^^^^^^^^^^^^^^^^^^^^^^^^^^^^
  File "/home/deni/Programming/Python/telegram-bot/venv/lib/python3.11/site-packages/telegram/_bot.py", line 3661, in get_updates
    await self._post(
  File "/home/deni/Programming/Python/telegram-bot/venv/lib/python3.11/site-packages/telegram/_bot.py", line 469, in _post
    return await self._do_post(
           ^^^^^^^^^^^^^^^^^^^^
  File "/home/deni/Programming/Python/telegram-bot/venv/lib/python3.11/site-packages/telegram/ext/_extbot.py", line 325, in _do_post
    return await super()._do_post(
           ^^^^^^^^^^^^^^^^^^^^^^^
  File "/home/deni/Programming/Python/telegram-bot/venv/lib/python3.11/site-packages/telegram/_bot.py", line 497, in _do_post
    return await request.post(
           ^^^^^^^^^^^^^^^^^^^
  File "/home/deni/Programming/Python/telegram-bot/venv/lib/python3.11/site-packages/telegram/request/_baserequest.py", line 168, in post
    result = await self._request_wrapper(
             ^^^^^^^^^^^^^^^^^^^^^^^^^^^^
  File "/home/deni/Programming/Python/telegram-bot/venv/lib/python3.11/site-packages/telegram/request/_baserequest.py", line 330, in _request_wrapper
    raise Conflict(message)
telegram.error.Conflict: Conflict: terminated by other getUpdates request; make sure that only one bot instance is running
